<?xml version="1.0"?>
<robot name="r12">
    <link name="base_link">
        <visual>
            <origin rpy="0 0 0" xyz="0 0 0.04"/>
            <geometry>
                <box size="0.22 0.22 0.08"/>
            </geometry>
        </visual>
        <collision>
            <origin rpy="0 0 0" xyz="0 0 0.04"/>
            <geometry>
                <box size="0.22 0.22 0.08"/>
            </geometry>
        </collision>
    </link>
  
    <joint name="waist_joint" type="revolute">
        <parent link="base_link"/>
        <child link="waist_shoulder_link"/>
        <origin xyz="0 0 0.0925" rpy="0 0 0"/>
        <limit lower="-3.14159" upper="3.14159" effort="0.1" velocity="0.005"/>
        <axis xyz="0 0 1"/>
    </joint>
  
    <link name="waist_shoulder_link">
        <visual>
            <origin rpy="0 0 0" xyz="0 0 0"/>
            <geometry>
                <cylinder radius="0.07" length="0.025"/>
            </geometry>
        </visual>
	<visual>
            <origin rpy="0 0 0" xyz="0.055 0 0.1315"/>
            <geometry>
                <box size="0.02 0.06 0.238"/>
            </geometry>
        </visual>
        <collision>
            <origin rpy="0 0 0" xyz="0 0 0"/>
            <geometry>
                <cylinder radius="0.07" length="0.025"/>
            </geometry>
        </collision>
	<collision>
            <origin rpy="0 0 0" xyz="0.055 0 0.1315"/>
            <geometry>
                <box size="0.02 0.06 0.238"/>
            </geometry>
        </collision>
    </link>

    <joint name="shoulder_joint" type="revolute">
        <parent link="waist_shoulder_link"/>
        <child link="shoulder_elbow_link"/>
        <origin xyz="0 0 0.2105" rpy="0 0 0"/>
        <limit lower="-3.14159" upper="3.14159" effort="0.1" velocity="0.005"/>
        <axis xyz="1 0 0"/>
    </joint>
    
    <link name="shoulder_elbow_link">
        <visual>
            <origin rpy="0 0 0" xyz="0 0 0.045"/>
            <geometry>
                <box size="0.045 0.095 0.460"/>
            </geometry>
        </visual>
	<visual>
            <origin rpy="0 0 0" xyz="0 0 -0.1325"/>
            <geometry>
                <box size="0.045 0.11094 0.105"/>
            </geometry>
        </visual>
	<visual>
            <origin rpy="0 0 0" xyz="0.03375 0 -0.03"/>
            <geometry>
                <box size="0.0225 0.07 0.15"/>
            </geometry>
        </visual>
	<visual>
            <origin rpy="-1.0472 0 0" xyz="0 0.053659 -0.053333"/>
            <geometry>
                <box size="0.045 0.092376 0.04"/>
            </geometry>
        </visual>
	<visual>
            <origin rpy="-0.349 0 0" xyz="0 0.053 -0.12506"/>
            <geometry>
                <box size="0.045 0.043403 0.111739"/>
            </geometry>
        </visual>
	<visual>
            <origin rpy="1.0472 0 0" xyz="0 -0.053659 -0.053333"/>
            <geometry>
                <box size="0.045 0.092376 0.04"/>
            </geometry>
        </visual>
	<visual>
            <origin rpy="0.349 0 0" xyz="0 -0.053 -0.12506"/>
            <geometry>
                <box size="0.045 0.043403 0.111739"/>
            </geometry>
        </visual>
        <collision>
            <origin rpy="0 0 0" xyz="0 0 0.045"/>
            <geometry>
                <box size="0.045 0.095 0.460"/>
            </geometry>
        </collision>
	<collision>
            <origin rpy="0 0 0" xyz="0 0 -0.1325"/>
            <geometry>
                <box size="0.045 0.11094 0.105"/>
            </geometry>
        </collision>
	<collision>
            <origin rpy="-1.0472 0 0" xyz="0 0.053659 -0.053333"/>
            <geometry>
                <box size="0.045 0.092376 0.04"/>
            </geometry>
        </collision>
	<collision>
            <origin rpy="-0.349 0 0" xyz="0 0.053 -0.12506"/>
            <geometry>
                <box size="0.045 0.043403 0.111739"/>
            </geometry>
        </collision>
	<collision>
            <origin rpy="1.0472 0 0" xyz="0 -0.053659 -0.053333"/>
            <geometry>
                <box size="0.045 0.092376 0.04"/>
            </geometry>
        </collision>
	<collision>
            <origin rpy="0.349 0 0" xyz="0 -0.053 -0.12506"/>
            <geometry>
                <box size="0.045 0.043403 0.111739"/>
            </geometry>
        </collision>
	<collision>
            <origin rpy="0 0 0" xyz="0.03375 0 -0.03"/>
            <geometry>
                <box size="0.0225 0.07 0.15"/>
            </geometry>
        </collision>
    </link>
    
    <joint name="elbow_joint" type="revolute">
        <parent link="shoulder_elbow_link"/>
        <child link="elbow_hand_link"/>
        <origin xyz="0.04 0 0.25" rpy="0 0 0"/>
        <limit lower="-2.26" upper="2.26" effort="0.1" velocity="0.005"/>
        <axis xyz="1 0 0"/>
    </joint>
    
    <link name="elbow_hand_link">
        <visual>
            <origin rpy="0 0 0" xyz="0 0 0.05"/>
            <geometry>
                <box size="0.025 0.06 0.45"/>
            </geometry>
        </visual>
        <visual>
            <origin rpy="0 -1.5708 0" xyz="-0.015 0 0"/>
            <geometry>
                <cylinder radius="0.02" length="0.005"/>
            </geometry>
        </visual>
        <collision>
            <origin rpy="0 0 0" xyz="0 0 0.05"/>
            <geometry>
                <box size="0.025 0.06 0.45"/>
            </geometry>
        </collision>
	<collision>
            <origin rpy="0 -1.5708 0" xyz="-0.015 0 0"/>
            <geometry>
                <cylinder radius="0.02" length="0.005"/>
            </geometry>
        </collision>
    </link>
    
    <joint name="hand_joint" type="revolute">
        <parent link="elbow_hand_link"/>
        <child link="hand_wrist_link"/>
        <origin xyz="-0.04 0 0.25" rpy="0 0 0"/>
        <limit lower="-2.09" upper="2.09" effort="0.1" velocity="0.005"/>
        <axis xyz="1 0 0"/>
    </joint>
    
    <link name="hand_wrist_link">
        <visual>
            <origin rpy="0 0 0" xyz="0 0 0"/>
            <geometry>
                <cylinder radius="0.0175" length="0.04"/>
            </geometry>
        </visual>
	<visual>
            <origin rpy="0 -1.5708 0" xyz="0.01375 0 0"/>
            <geometry>
                <cylinder radius="0.01" length="0.0275"/>
            </geometry>
        </visual>
        <collision>
            <origin rpy="0 0 0" xyz="0 0 0"/>
            <geometry>
                <cylinder radius="0.0175" length="0.04"/>
            </geometry>
        </collision>
	<collision>
            <origin rpy="0 -1.5708 0" xyz="0.01375 0 0"/>
            <geometry>
                <cylinder radius="0.01" length="0.0275"/>
            </geometry>
        </collision>
    </link>
    
    <joint name="wrist_joint" type="revolute">
        <parent link="hand_wrist_link"/>
        <child link="wrist_tool_link"/>
        <origin xyz="0 0 0.02" rpy="0 0 0"/>
        <limit lower="-3.14159" upper="3.14159" effort="0.1" velocity="0.005"/>
        <axis xyz="0 0 1"/>
    </joint>
    
    <link name="wrist_tool_link">
        <visual>
            <origin rpy="0 0 0" xyz="0 0 0.01"/>
            <geometry>
                <cylinder radius="0.0175" length="0.02"/>
            </geometry>
        </visual>
        <collision>
            <origin rpy="0 0 0" xyz="0 0 0.01"/>
            <geometry>
                <cylinder radius="0.0175" length="0.02"/>
            </geometry>
        </collision>
    </link>
    
</robot>
